2019-08-20 16:42:15,376 ERROR: Exception on /query/clean-fc [POST] [in c:\arcgis\pro\bin\python\envs\flask\lib\site-packages\flask\app.py:1761]
Traceback (most recent call last):
  File "c:\arcgis\pro\bin\python\envs\flask\lib\site-packages\flask\app.py", line 2292, in wsgi_app
    response = self.full_dispatch_request()
  File "c:\arcgis\pro\bin\python\envs\flask\lib\site-packages\flask\app.py", line 1815, in full_dispatch_request
    rv = self.handle_user_exception(e)
  File "c:\arcgis\pro\bin\python\envs\flask\lib\site-packages\flask\app.py", line 1718, in handle_user_exception
    reraise(exc_type, exc_value, tb)
  File "c:\arcgis\pro\bin\python\envs\flask\lib\site-packages\flask\_compat.py", line 35, in reraise
    raise value
  File "c:\arcgis\pro\bin\python\envs\flask\lib\site-packages\flask\app.py", line 1813, in full_dispatch_request
    rv = self.dispatch_request()
  File "c:\arcgis\pro\bin\python\envs\flask\lib\site-packages\flask\app.py", line 1799, in dispatch_request
    return self.view_functions[rule.endpoint](**req.view_args)
  File "c:\arcgis\pro\bin\python\envs\flask\lib\site-packages\flask_login\utils.py", line 261, in decorated_view
    return func(*args, **kwargs)
  File "C:\Users\arcgis\Documents\GitHub\wdc-integration\app\routes\query_routes.py", line 113, in clean_pai_fc
    features_for_delete.append(feature.attribute['objectid'])
AttributeError: 'Feature' object has no attribute 'attribute'
2019-08-20 16:42:24,425 ERROR: Exception on /query/clean-fc [POST] [in c:\arcgis\pro\bin\python\envs\flask\lib\site-packages\flask\app.py:1761]
Traceback (most recent call last):
  File "c:\arcgis\pro\bin\python\envs\flask\lib\site-packages\flask\app.py", line 2292, in wsgi_app
    response = self.full_dispatch_request()
  File "c:\arcgis\pro\bin\python\envs\flask\lib\site-packages\flask\app.py", line 1815, in full_dispatch_request
    rv = self.handle_user_exception(e)
  File "c:\arcgis\pro\bin\python\envs\flask\lib\site-packages\flask\app.py", line 1718, in handle_user_exception
    reraise(exc_type, exc_value, tb)
  File "c:\arcgis\pro\bin\python\envs\flask\lib\site-packages\flask\_compat.py", line 35, in reraise
    raise value
  File "c:\arcgis\pro\bin\python\envs\flask\lib\site-packages\flask\app.py", line 1813, in full_dispatch_request
    rv = self.dispatch_request()
  File "c:\arcgis\pro\bin\python\envs\flask\lib\site-packages\flask\app.py", line 1799, in dispatch_request
    return self.view_functions[rule.endpoint](**req.view_args)
  File "c:\arcgis\pro\bin\python\envs\flask\lib\site-packages\flask_login\utils.py", line 261, in decorated_view
    return func(*args, **kwargs)
  File "C:\Users\arcgis\Documents\GitHub\wdc-integration\app\routes\query_routes.py", line 113, in clean_pai_fc
    features_for_delete.append(feature.attribute['objectid'])
AttributeError: 'Feature' object has no attribute 'attribute'
2019-08-20 16:43:26,491 INFO: Microblog startup [in C:\Users\arcgis\Documents\GitHub\wdc-integration\app\__init__.py:43]
2019-08-20 16:45:11,008 INFO: Microblog startup [in C:\Users\arcgis\Documents\GitHub\wdc-integration\app\__init__.py:43]
2019-08-20 16:46:54,029 INFO: Microblog startup [in C:\Users\arcgis\Documents\GitHub\wdc-integration\app\__init__.py:43]
2019-08-21 16:25:45,025 INFO: Microblog startup [in C:\Users\arcgis\Documents\GitHub\wdc-integration\app\__init__.py:43]
2019-08-21 16:48:29,560 INFO: Microblog startup [in C:\Users\arcgis\Documents\GitHub\wdc-integration\app\__init__.py:43]
2019-08-21 16:49:16,557 INFO: Microblog startup [in C:\Users\arcgis\Documents\GitHub\wdc-integration\app\__init__.py:43]
2019-08-21 16:50:07,454 ERROR: Exception on /admin/create-user [POST] [in c:\arcgis\pro\bin\python\envs\flask\lib\site-packages\flask\app.py:1761]
Traceback (most recent call last):
  File "c:\arcgis\pro\bin\python\envs\flask\lib\site-packages\flask\app.py", line 2292, in wsgi_app
    response = self.full_dispatch_request()
  File "c:\arcgis\pro\bin\python\envs\flask\lib\site-packages\flask\app.py", line 1815, in full_dispatch_request
    rv = self.handle_user_exception(e)
  File "c:\arcgis\pro\bin\python\envs\flask\lib\site-packages\flask\app.py", line 1718, in handle_user_exception
    reraise(exc_type, exc_value, tb)
  File "c:\arcgis\pro\bin\python\envs\flask\lib\site-packages\flask\_compat.py", line 35, in reraise
    raise value
  File "c:\arcgis\pro\bin\python\envs\flask\lib\site-packages\flask\app.py", line 1813, in full_dispatch_request
    rv = self.dispatch_request()
  File "c:\arcgis\pro\bin\python\envs\flask\lib\site-packages\flask\app.py", line 1799, in dispatch_request
    return self.view_functions[rule.endpoint](**req.view_args)
  File "c:\arcgis\pro\bin\python\envs\flask\lib\site-packages\flask_login\utils.py", line 261, in decorated_view
    return func(*args, **kwargs)
  File "C:\Users\arcgis\Documents\GitHub\wdc-integration\app\routes\admin_routes.py", line 140, in form_create_user
    target_portal = GIS("https://swcs.maps.arcgis.com", "james_jones_swcs", "QWerty654321@!")
  File "c:\arcgis\pro\bin\python\envs\flask\lib\site-packages\arcgis\gis\__init__.py", line 334, in __init__
    raise e
  File "c:\arcgis\pro\bin\python\envs\flask\lib\site-packages\arcgis\gis\__init__.py", line 322, in __init__
    referer=self._referer)
  File "c:\arcgis\pro\bin\python\envs\flask\lib\site-packages\arcgis\_impl\portalpy.py", line 163, in __init__
    client_id=client_id)
  File "c:\arcgis\pro\bin\python\envs\flask\lib\site-packages\arcgis\_impl\connection.py", line 308, in __init__
    self.login(username, password, expiration, client_id)
  File "c:\arcgis\pro\bin\python\envs\flask\lib\site-packages\arcgis\_impl\connection.py", line 559, in login
    newtoken = self.generate_token(username, password, expiration, client_id)
  File "c:\arcgis\pro\bin\python\envs\flask\lib\site-packages\arcgis\_impl\connection.py", line 424, in generate_token
    ssl=True, add_token=False)
  File "c:\arcgis\pro\bin\python\envs\flask\lib\site-packages\arcgis\_impl\connection.py", line 1177, in post
    self._handle_json_error(resp_json['error'], errorcode)
  File "c:\arcgis\pro\bin\python\envs\flask\lib\site-packages\arcgis\_impl\connection.py", line 1198, in _handle_json_error
    raise RuntimeError(errormessage)
RuntimeError: Unable to generate token.
Invalid username or password.
(Error Code: 400)
2019-08-21 16:52:24,029 INFO: Microblog startup [in C:\Users\arcgis\Documents\GitHub\wdc-integration\app\__init__.py:43]
2019-08-21 16:52:41,590 ERROR: Exception on /admin/create-user [POST] [in c:\arcgis\pro\bin\python\envs\flask\lib\site-packages\flask\app.py:1761]
Traceback (most recent call last):
  File "c:\arcgis\pro\bin\python\envs\flask\lib\site-packages\flask\app.py", line 2292, in wsgi_app
    response = self.full_dispatch_request()
  File "c:\arcgis\pro\bin\python\envs\flask\lib\site-packages\flask\app.py", line 1815, in full_dispatch_request
    rv = self.handle_user_exception(e)
  File "c:\arcgis\pro\bin\python\envs\flask\lib\site-packages\flask\app.py", line 1718, in handle_user_exception
    reraise(exc_type, exc_value, tb)
  File "c:\arcgis\pro\bin\python\envs\flask\lib\site-packages\flask\_compat.py", line 35, in reraise
    raise value
  File "c:\arcgis\pro\bin\python\envs\flask\lib\site-packages\flask\app.py", line 1813, in full_dispatch_request
    rv = self.dispatch_request()
  File "c:\arcgis\pro\bin\python\envs\flask\lib\site-packages\flask\app.py", line 1799, in dispatch_request
    return self.view_functions[rule.endpoint](**req.view_args)
  File "c:\arcgis\pro\bin\python\envs\flask\lib\site-packages\flask_login\utils.py", line 261, in decorated_view
    return func(*args, **kwargs)
  File "C:\Users\arcgis\Documents\GitHub\wdc-integration\app\routes\admin_routes.py", line 140, in form_create_user
    target_portal = GIS("https://swcs.maps.arcgis.com", "james_jones_swcs", "QWerty654321@!")
  File "c:\arcgis\pro\bin\python\envs\flask\lib\site-packages\arcgis\gis\__init__.py", line 334, in __init__
    raise e
  File "c:\arcgis\pro\bin\python\envs\flask\lib\site-packages\arcgis\gis\__init__.py", line 322, in __init__
    referer=self._referer)
  File "c:\arcgis\pro\bin\python\envs\flask\lib\site-packages\arcgis\_impl\portalpy.py", line 163, in __init__
    client_id=client_id)
  File "c:\arcgis\pro\bin\python\envs\flask\lib\site-packages\arcgis\_impl\connection.py", line 308, in __init__
    self.login(username, password, expiration, client_id)
  File "c:\arcgis\pro\bin\python\envs\flask\lib\site-packages\arcgis\_impl\connection.py", line 559, in login
    newtoken = self.generate_token(username, password, expiration, client_id)
  File "c:\arcgis\pro\bin\python\envs\flask\lib\site-packages\arcgis\_impl\connection.py", line 424, in generate_token
    ssl=True, add_token=False)
  File "c:\arcgis\pro\bin\python\envs\flask\lib\site-packages\arcgis\_impl\connection.py", line 1177, in post
    self._handle_json_error(resp_json['error'], errorcode)
  File "c:\arcgis\pro\bin\python\envs\flask\lib\site-packages\arcgis\_impl\connection.py", line 1198, in _handle_json_error
    raise RuntimeError(errormessage)
RuntimeError: Unable to generate token.
Invalid username or password.
(Error Code: 400)
2019-08-21 19:04:50,612 INFO: Beginning unzip of file. [in C:\Users\arcgis\Documents\GitHub\wdc-integration\app\scripts\unzip.py:9]
2019-08-21 19:08:01,976 INFO: Successfully unzipped file. [in C:\Users\arcgis\Documents\GitHub\wdc-integration\app\scripts\unzip.py:16]
2019-08-22 00:31:56,997 INFO: Microblog startup [in C:\Users\arcgis\Documents\GitHub\wdc-integration\app\__init__.py:43]
