2019-06-26 23:31:44,405 INFO: Microblog startup [in /home/dif_user/wdc-integration/app/__init__.py:37]
2019-06-26 23:31:44,485 INFO: Microblog startup [in /home/dif_user/wdc-integration/app/__init__.py:37]
2019-06-26 23:31:44,628 INFO: Microblog startup [in /home/dif_user/wdc-integration/app/__init__.py:37]
2019-06-26 23:31:44,698 INFO: Microblog startup [in /home/dif_user/wdc-integration/app/__init__.py:37]
2019-06-26 23:31:51,573 ERROR: Exception on / [GET] [in /home/dif_user/wdc-integration/venv/lib/python3.6/site-packages/flask/app.py:1761]
Traceback (most recent call last):
  File "/home/dif_user/wdc-integration/venv/lib/python3.6/site-packages/flask/app.py", line 2292, in wsgi_app
    response = self.full_dispatch_request()
  File "/home/dif_user/wdc-integration/venv/lib/python3.6/site-packages/flask/app.py", line 1815, in full_dispatch_request
    rv = self.handle_user_exception(e)
  File "/home/dif_user/wdc-integration/venv/lib/python3.6/site-packages/flask/app.py", line 1718, in handle_user_exception
    reraise(exc_type, exc_value, tb)
  File "/home/dif_user/wdc-integration/venv/lib/python3.6/site-packages/flask/_compat.py", line 35, in reraise
    raise value
  File "/home/dif_user/wdc-integration/venv/lib/python3.6/site-packages/flask/app.py", line 1813, in full_dispatch_request
    rv = self.dispatch_request()
  File "/home/dif_user/wdc-integration/venv/lib/python3.6/site-packages/flask/app.py", line 1799, in dispatch_request
    return self.view_functions[rule.endpoint](**req.view_args)
  File "/home/dif_user/wdc-integration/venv/lib/python3.6/site-packages/flask_login/utils.py", line 260, in decorated_view
    return current_app.login_manager.unauthorized()
  File "/home/dif_user/wdc-integration/venv/lib/python3.6/site-packages/flask_login/login_manager.py", line 167, in unauthorized
    flash(self.login_message, category=self.login_message_category)
  File "/home/dif_user/wdc-integration/venv/lib/python3.6/site-packages/flask/helpers.py", line 410, in flash
    session['_flashes'] = flashes
  File "/home/dif_user/wdc-integration/venv/lib/python3.6/site-packages/werkzeug/local.py", line 350, in __setitem__
    self._get_current_object()[key] = value
  File "/home/dif_user/wdc-integration/venv/lib/python3.6/site-packages/flask/sessions.py", line 101, in _fail
    raise RuntimeError('The session is unavailable because no secret '
RuntimeError: The session is unavailable because no secret key was set.  Set the secret_key on the application to something unique and secret.
2019-06-26 23:31:55,574 ERROR: Exception on / [GET] [in /home/dif_user/wdc-integration/venv/lib/python3.6/site-packages/flask/app.py:1761]
Traceback (most recent call last):
  File "/home/dif_user/wdc-integration/venv/lib/python3.6/site-packages/flask/app.py", line 2292, in wsgi_app
    response = self.full_dispatch_request()
  File "/home/dif_user/wdc-integration/venv/lib/python3.6/site-packages/flask/app.py", line 1815, in full_dispatch_request
    rv = self.handle_user_exception(e)
  File "/home/dif_user/wdc-integration/venv/lib/python3.6/site-packages/flask/app.py", line 1718, in handle_user_exception
    reraise(exc_type, exc_value, tb)
  File "/home/dif_user/wdc-integration/venv/lib/python3.6/site-packages/flask/_compat.py", line 35, in reraise
    raise value
  File "/home/dif_user/wdc-integration/venv/lib/python3.6/site-packages/flask/app.py", line 1813, in full_dispatch_request
    rv = self.dispatch_request()
  File "/home/dif_user/wdc-integration/venv/lib/python3.6/site-packages/flask/app.py", line 1799, in dispatch_request
    return self.view_functions[rule.endpoint](**req.view_args)
  File "/home/dif_user/wdc-integration/venv/lib/python3.6/site-packages/flask_login/utils.py", line 260, in decorated_view
    return current_app.login_manager.unauthorized()
  File "/home/dif_user/wdc-integration/venv/lib/python3.6/site-packages/flask_login/login_manager.py", line 167, in unauthorized
    flash(self.login_message, category=self.login_message_category)
  File "/home/dif_user/wdc-integration/venv/lib/python3.6/site-packages/flask/helpers.py", line 410, in flash
    session['_flashes'] = flashes
  File "/home/dif_user/wdc-integration/venv/lib/python3.6/site-packages/werkzeug/local.py", line 350, in __setitem__
    self._get_current_object()[key] = value
  File "/home/dif_user/wdc-integration/venv/lib/python3.6/site-packages/flask/sessions.py", line 101, in _fail
    raise RuntimeError('The session is unavailable because no secret '
RuntimeError: The session is unavailable because no secret key was set.  Set the secret_key on the application to something unique and secret.
2019-06-26 23:35:36,427 INFO: Microblog startup [in /home/dif_user/wdc-integration/app/__init__.py:37]
2019-06-26 23:35:36,615 INFO: Microblog startup [in /home/dif_user/wdc-integration/app/__init__.py:37]
2019-06-26 23:35:36,761 INFO: Microblog startup [in /home/dif_user/wdc-integration/app/__init__.py:37]
2019-06-26 23:35:36,775 INFO: Microblog startup [in /home/dif_user/wdc-integration/app/__init__.py:37]
2019-06-26 23:35:42,607 ERROR: Exception on / [GET] [in /home/dif_user/wdc-integration/venv/lib/python3.6/site-packages/flask/app.py:1761]
Traceback (most recent call last):
  File "/home/dif_user/wdc-integration/venv/lib/python3.6/site-packages/flask/app.py", line 2292, in wsgi_app
    response = self.full_dispatch_request()
  File "/home/dif_user/wdc-integration/venv/lib/python3.6/site-packages/flask/app.py", line 1815, in full_dispatch_request
    rv = self.handle_user_exception(e)
  File "/home/dif_user/wdc-integration/venv/lib/python3.6/site-packages/flask/app.py", line 1718, in handle_user_exception
    reraise(exc_type, exc_value, tb)
  File "/home/dif_user/wdc-integration/venv/lib/python3.6/site-packages/flask/_compat.py", line 35, in reraise
    raise value
  File "/home/dif_user/wdc-integration/venv/lib/python3.6/site-packages/flask/app.py", line 1813, in full_dispatch_request
    rv = self.dispatch_request()
  File "/home/dif_user/wdc-integration/venv/lib/python3.6/site-packages/flask/app.py", line 1799, in dispatch_request
    return self.view_functions[rule.endpoint](**req.view_args)
  File "/home/dif_user/wdc-integration/venv/lib/python3.6/site-packages/flask_login/utils.py", line 260, in decorated_view
    return current_app.login_manager.unauthorized()
  File "/home/dif_user/wdc-integration/venv/lib/python3.6/site-packages/flask_login/login_manager.py", line 167, in unauthorized
    flash(self.login_message, category=self.login_message_category)
  File "/home/dif_user/wdc-integration/venv/lib/python3.6/site-packages/flask/helpers.py", line 410, in flash
    session['_flashes'] = flashes
  File "/home/dif_user/wdc-integration/venv/lib/python3.6/site-packages/werkzeug/local.py", line 350, in __setitem__
    self._get_current_object()[key] = value
  File "/home/dif_user/wdc-integration/venv/lib/python3.6/site-packages/flask/sessions.py", line 101, in _fail
    raise RuntimeError('The session is unavailable because no secret '
RuntimeError: The session is unavailable because no secret key was set.  Set the secret_key on the application to something unique and secret.
2019-06-26 23:36:04,469 INFO: Microblog startup [in /home/dif_user/wdc-integration/app/__init__.py:37]
2019-06-26 23:36:04,519 INFO: Microblog startup [in /home/dif_user/wdc-integration/app/__init__.py:37]
2019-06-26 23:36:04,768 INFO: Microblog startup [in /home/dif_user/wdc-integration/app/__init__.py:37]
2019-06-26 23:36:04,808 INFO: Microblog startup [in /home/dif_user/wdc-integration/app/__init__.py:37]
2019-06-26 23:36:16,546 ERROR: Exception on / [GET] [in /home/dif_user/wdc-integration/venv/lib/python3.6/site-packages/flask/app.py:1761]
Traceback (most recent call last):
  File "/home/dif_user/wdc-integration/venv/lib/python3.6/site-packages/flask/app.py", line 2292, in wsgi_app
    response = self.full_dispatch_request()
  File "/home/dif_user/wdc-integration/venv/lib/python3.6/site-packages/flask/app.py", line 1815, in full_dispatch_request
    rv = self.handle_user_exception(e)
  File "/home/dif_user/wdc-integration/venv/lib/python3.6/site-packages/flask/app.py", line 1718, in handle_user_exception
    reraise(exc_type, exc_value, tb)
  File "/home/dif_user/wdc-integration/venv/lib/python3.6/site-packages/flask/_compat.py", line 35, in reraise
    raise value
  File "/home/dif_user/wdc-integration/venv/lib/python3.6/site-packages/flask/app.py", line 1813, in full_dispatch_request
    rv = self.dispatch_request()
  File "/home/dif_user/wdc-integration/venv/lib/python3.6/site-packages/flask/app.py", line 1799, in dispatch_request
    return self.view_functions[rule.endpoint](**req.view_args)
  File "/home/dif_user/wdc-integration/venv/lib/python3.6/site-packages/flask_login/utils.py", line 260, in decorated_view
    return current_app.login_manager.unauthorized()
  File "/home/dif_user/wdc-integration/venv/lib/python3.6/site-packages/flask_login/login_manager.py", line 167, in unauthorized
    flash(self.login_message, category=self.login_message_category)
  File "/home/dif_user/wdc-integration/venv/lib/python3.6/site-packages/flask/helpers.py", line 410, in flash
    session['_flashes'] = flashes
  File "/home/dif_user/wdc-integration/venv/lib/python3.6/site-packages/werkzeug/local.py", line 350, in __setitem__
    self._get_current_object()[key] = value
  File "/home/dif_user/wdc-integration/venv/lib/python3.6/site-packages/flask/sessions.py", line 101, in _fail
    raise RuntimeError('The session is unavailable because no secret '
RuntimeError: The session is unavailable because no secret key was set.  Set the secret_key on the application to something unique and secret.
2019-06-26 23:37:07,585 INFO: Microblog startup [in /home/dif_user/wdc-integration/app/__init__.py:37]
2019-06-26 23:37:07,765 INFO: Microblog startup [in /home/dif_user/wdc-integration/app/__init__.py:37]
2019-06-26 23:37:07,791 INFO: Microblog startup [in /home/dif_user/wdc-integration/app/__init__.py:37]
2019-06-26 23:37:07,939 INFO: Microblog startup [in /home/dif_user/wdc-integration/app/__init__.py:37]
